[2025-04-16T17:17:51.452-0500] {local_task_job_runner.py:123} INFO - ::group::Pre task execution logs
[2025-04-16T17:17:51.455-0500] {taskinstance.py:2614} INFO - Dependencies all met for dep_context=non-requeueable deps ti=<TaskInstance: multi_city_weather_pipeline.fetch_weather_for_all_cities scheduled__2025-04-16T21:00:00+00:00 [queued]>
[2025-04-16T17:17:51.457-0500] {taskinstance.py:2614} INFO - Dependencies all met for dep_context=requeueable deps ti=<TaskInstance: multi_city_weather_pipeline.fetch_weather_for_all_cities scheduled__2025-04-16T21:00:00+00:00 [queued]>
[2025-04-16T17:17:51.458-0500] {taskinstance.py:2867} INFO - Starting attempt 1 of 2
[2025-04-16T17:17:51.464-0500] {taskinstance.py:2890} INFO - Executing <Task(PythonOperator): fetch_weather_for_all_cities> on 2025-04-16 21:00:00+00:00
[2025-04-16T17:17:51.466-0500] {standard_task_runner.py:72} INFO - Started process 30717 to run task
[2025-04-16T17:17:51.469-0500] {standard_task_runner.py:104} INFO - Running: ['airflow', 'tasks', 'run', 'multi_city_weather_pipeline', 'fetch_weather_for_all_cities', 'scheduled__2025-04-16T21:00:00+00:00', '--job-id', '125', '--raw', '--subdir', 'DAGS_FOLDER/weather_pipeline_dag.py', '--cfg-path', '/var/folders/4n/q_76d_d57mb9q1qtrf4mvh940000gn/T/tmphkq11wnk']
[2025-04-16T17:17:51.470-0500] {standard_task_runner.py:105} INFO - Job 125: Subtask fetch_weather_for_all_cities
[2025-04-16T17:17:51.487-0500] {task_command.py:467} INFO - Running <TaskInstance: multi_city_weather_pipeline.fetch_weather_for_all_cities scheduled__2025-04-16T21:00:00+00:00 [running]> on host ramyas-macbook-air.local
[2025-04-16T17:17:51.507-0500] {taskinstance.py:3134} INFO - Exporting env vars: AIRFLOW_CTX_DAG_OWNER='airflow' AIRFLOW_CTX_DAG_ID='multi_city_weather_pipeline' AIRFLOW_CTX_TASK_ID='fetch_weather_for_all_cities' AIRFLOW_CTX_EXECUTION_DATE='2025-04-16T21:00:00+00:00' AIRFLOW_CTX_TRY_NUMBER='1' AIRFLOW_CTX_DAG_RUN_ID='scheduled__2025-04-16T21:00:00+00:00'
[2025-04-16T17:17:51.508-0500] {logging_mixin.py:190} INFO - Task instance is in running state
[2025-04-16T17:17:51.508-0500] {logging_mixin.py:190} INFO -  Previous state of the Task instance: queued
[2025-04-16T17:17:51.508-0500] {logging_mixin.py:190} INFO - Current task name:fetch_weather_for_all_cities state:running start_date:2025-04-16 22:17:51.456049+00:00
[2025-04-16T17:17:51.509-0500] {logging_mixin.py:190} INFO - Dag name:multi_city_weather_pipeline and current dag run status:running
[2025-04-16T17:17:51.509-0500] {taskinstance.py:732} INFO - ::endgroup::
[2025-04-16T17:17:51.512-0500] {taskinstance.py:3313} ERROR - Task failed with exception
Traceback (most recent call last):
  File "/Library/Frameworks/Python.framework/Versions/3.10/lib/python3.10/site-packages/urllib3/connection.py", line 198, in _new_conn
    sock = connection.create_connection(
  File "/Library/Frameworks/Python.framework/Versions/3.10/lib/python3.10/site-packages/urllib3/util/connection.py", line 60, in create_connection
    for res in socket.getaddrinfo(host, port, family, socket.SOCK_STREAM):
  File "/Library/Frameworks/Python.framework/Versions/3.10/lib/python3.10/socket.py", line 955, in getaddrinfo
    for res in _socket.getaddrinfo(host, port, family, type, proto, flags):
socket.gaierror: [Errno 8] nodename nor servname provided, or not known

The above exception was the direct cause of the following exception:

Traceback (most recent call last):
  File "/Library/Frameworks/Python.framework/Versions/3.10/lib/python3.10/site-packages/urllib3/connectionpool.py", line 787, in urlopen
    response = self._make_request(
  File "/Library/Frameworks/Python.framework/Versions/3.10/lib/python3.10/site-packages/urllib3/connectionpool.py", line 488, in _make_request
    raise new_e
  File "/Library/Frameworks/Python.framework/Versions/3.10/lib/python3.10/site-packages/urllib3/connectionpool.py", line 464, in _make_request
    self._validate_conn(conn)
  File "/Library/Frameworks/Python.framework/Versions/3.10/lib/python3.10/site-packages/urllib3/connectionpool.py", line 1093, in _validate_conn
    conn.connect()
  File "/Library/Frameworks/Python.framework/Versions/3.10/lib/python3.10/site-packages/urllib3/connection.py", line 704, in connect
    self.sock = sock = self._new_conn()
  File "/Library/Frameworks/Python.framework/Versions/3.10/lib/python3.10/site-packages/urllib3/connection.py", line 205, in _new_conn
    raise NameResolutionError(self.host, self, e) from e
urllib3.exceptions.NameResolutionError: <urllib3.connection.HTTPSConnection object at 0x120fa76a0>: Failed to resolve 'api.openweathermap.org' ([Errno 8] nodename nor servname provided, or not known)

The above exception was the direct cause of the following exception:

Traceback (most recent call last):
  File "/Library/Frameworks/Python.framework/Versions/3.10/lib/python3.10/site-packages/requests/adapters.py", line 667, in send
    resp = conn.urlopen(
  File "/Library/Frameworks/Python.framework/Versions/3.10/lib/python3.10/site-packages/urllib3/connectionpool.py", line 841, in urlopen
    retries = retries.increment(
  File "/Library/Frameworks/Python.framework/Versions/3.10/lib/python3.10/site-packages/urllib3/util/retry.py", line 519, in increment
    raise MaxRetryError(_pool, url, reason) from reason  # type: ignore[arg-type]
urllib3.exceptions.MaxRetryError: HTTPSConnectionPool(host='api.openweathermap.org', port=443): Max retries exceeded with url: /data/2.5/weather?q=Dallas&appid=e07be197f3d0a37e1661e03509a61797&units=metric (Caused by NameResolutionError("<urllib3.connection.HTTPSConnection object at 0x120fa76a0>: Failed to resolve 'api.openweathermap.org' ([Errno 8] nodename nor servname provided, or not known)"))

During handling of the above exception, another exception occurred:

Traceback (most recent call last):
  File "/Library/Frameworks/Python.framework/Versions/3.10/lib/python3.10/site-packages/airflow/models/taskinstance.py", line 768, in _execute_task
    result = _execute_callable(context=context, **execute_callable_kwargs)
  File "/Library/Frameworks/Python.framework/Versions/3.10/lib/python3.10/site-packages/airflow/models/taskinstance.py", line 734, in _execute_callable
    return ExecutionCallableRunner(
  File "/Library/Frameworks/Python.framework/Versions/3.10/lib/python3.10/site-packages/airflow/utils/operator_helpers.py", line 252, in run
    return self.func(*args, **kwargs)
  File "/Library/Frameworks/Python.framework/Versions/3.10/lib/python3.10/site-packages/airflow/models/baseoperator.py", line 424, in wrapper
    return func(self, *args, **kwargs)
  File "/Library/Frameworks/Python.framework/Versions/3.10/lib/python3.10/site-packages/airflow/operators/python.py", line 238, in execute
    return_value = self.execute_callable()
  File "/Library/Frameworks/Python.framework/Versions/3.10/lib/python3.10/site-packages/airflow/operators/python.py", line 256, in execute_callable
    return runner.run(*self.op_args, **self.op_kwargs)
  File "/Library/Frameworks/Python.framework/Versions/3.10/lib/python3.10/site-packages/airflow/utils/operator_helpers.py", line 252, in run
    return self.func(*args, **kwargs)
  File "/Users/Ramya_Rangaraju/Data_engineering_projects/weather_pipeline/dags/weather_pipeline_dag.py", line 35, in <lambda>
    python_callable=lambda: fetch_weather_for_cities(cities)
  File "/Users/Ramya_Rangaraju/Data_engineering_projects/weather_pipeline/scripts/fetch_weather.py", line 36, in fetch_weather_for_cities
    result = fetch_weather(city)
  File "/Users/Ramya_Rangaraju/Data_engineering_projects/weather_pipeline/scripts/fetch_weather.py", line 14, in fetch_weather
    response = requests.get(url)
  File "/Library/Frameworks/Python.framework/Versions/3.10/lib/python3.10/site-packages/requests/api.py", line 73, in get
    return request("get", url, params=params, **kwargs)
  File "/Library/Frameworks/Python.framework/Versions/3.10/lib/python3.10/site-packages/requests/api.py", line 59, in request
    return session.request(method=method, url=url, **kwargs)
  File "/Library/Frameworks/Python.framework/Versions/3.10/lib/python3.10/site-packages/requests/sessions.py", line 589, in request
    resp = self.send(prep, **send_kwargs)
  File "/Library/Frameworks/Python.framework/Versions/3.10/lib/python3.10/site-packages/requests/sessions.py", line 703, in send
    r = adapter.send(request, **kwargs)
  File "/Library/Frameworks/Python.framework/Versions/3.10/lib/python3.10/site-packages/requests/adapters.py", line 700, in send
    raise ConnectionError(e, request=request)
requests.exceptions.ConnectionError: HTTPSConnectionPool(host='api.openweathermap.org', port=443): Max retries exceeded with url: /data/2.5/weather?q=Dallas&appid=e07be197f3d0a37e1661e03509a61797&units=metric (Caused by NameResolutionError("<urllib3.connection.HTTPSConnection object at 0x120fa76a0>: Failed to resolve 'api.openweathermap.org' ([Errno 8] nodename nor servname provided, or not known)"))
[2025-04-16T17:17:51.525-0500] {logging_mixin.py:190} INFO - Task instance in failure state
[2025-04-16T17:17:51.525-0500] {logging_mixin.py:190} INFO - Task start:2025-04-16 22:17:51.456049+00:00 end:2025-04-16 22:17:51.525314+00:00 duration:0.069265
[2025-04-16T17:17:51.525-0500] {logging_mixin.py:190} INFO - Task:<Task(PythonOperator): fetch_weather_for_all_cities> dag:<DAG: multi_city_weather_pipeline> dagrun:<DagRun multi_city_weather_pipeline @ 2025-04-16 21:00:00+00:00: scheduled__2025-04-16T21:00:00+00:00, state:running, queued_at: 2025-04-16 22:09:26.408065+00:00. externally triggered: False>
[2025-04-16T17:17:51.526-0500] {logging_mixin.py:190} INFO - Failure caused by HTTPSConnectionPool(host='api.openweathermap.org', port=443): Max retries exceeded with url: /data/2.5/weather?q=Dallas&appid=e07be197f3d0a37e1661e03509a61797&units=metric (Caused by NameResolutionError("<urllib3.connection.HTTPSConnection object at 0x120fa76a0>: Failed to resolve 'api.openweathermap.org' ([Errno 8] nodename nor servname provided, or not known)"))
[2025-04-16T17:17:51.526-0500] {taskinstance.py:1226} INFO - Marking task as UP_FOR_RETRY. dag_id=multi_city_weather_pipeline, task_id=fetch_weather_for_all_cities, run_id=scheduled__2025-04-16T21:00:00+00:00, execution_date=20250416T210000, start_date=20250416T221751, end_date=20250416T221751
[2025-04-16T17:17:51.532-0500] {taskinstance.py:341} INFO - ::group::Post task execution logs
[2025-04-16T17:17:51.533-0500] {standard_task_runner.py:124} ERROR - Failed to execute job 125 for task fetch_weather_for_all_cities (HTTPSConnectionPool(host='api.openweathermap.org', port=443): Max retries exceeded with url: /data/2.5/weather?q=Dallas&appid=e07be197f3d0a37e1661e03509a61797&units=metric (Caused by NameResolutionError("<urllib3.connection.HTTPSConnection object at 0x120fa76a0>: Failed to resolve 'api.openweathermap.org' ([Errno 8] nodename nor servname provided, or not known)")); 30717)
Traceback (most recent call last):
  File "/Library/Frameworks/Python.framework/Versions/3.10/lib/python3.10/site-packages/urllib3/connection.py", line 198, in _new_conn
    sock = connection.create_connection(
  File "/Library/Frameworks/Python.framework/Versions/3.10/lib/python3.10/site-packages/urllib3/util/connection.py", line 60, in create_connection
    for res in socket.getaddrinfo(host, port, family, socket.SOCK_STREAM):
  File "/Library/Frameworks/Python.framework/Versions/3.10/lib/python3.10/socket.py", line 955, in getaddrinfo
    for res in _socket.getaddrinfo(host, port, family, type, proto, flags):
socket.gaierror: [Errno 8] nodename nor servname provided, or not known

The above exception was the direct cause of the following exception:

Traceback (most recent call last):
  File "/Library/Frameworks/Python.framework/Versions/3.10/lib/python3.10/site-packages/urllib3/connectionpool.py", line 787, in urlopen
    response = self._make_request(
  File "/Library/Frameworks/Python.framework/Versions/3.10/lib/python3.10/site-packages/urllib3/connectionpool.py", line 488, in _make_request
    raise new_e
  File "/Library/Frameworks/Python.framework/Versions/3.10/lib/python3.10/site-packages/urllib3/connectionpool.py", line 464, in _make_request
    self._validate_conn(conn)
  File "/Library/Frameworks/Python.framework/Versions/3.10/lib/python3.10/site-packages/urllib3/connectionpool.py", line 1093, in _validate_conn
    conn.connect()
  File "/Library/Frameworks/Python.framework/Versions/3.10/lib/python3.10/site-packages/urllib3/connection.py", line 704, in connect
    self.sock = sock = self._new_conn()
  File "/Library/Frameworks/Python.framework/Versions/3.10/lib/python3.10/site-packages/urllib3/connection.py", line 205, in _new_conn
    raise NameResolutionError(self.host, self, e) from e
urllib3.exceptions.NameResolutionError: <urllib3.connection.HTTPSConnection object at 0x120fa76a0>: Failed to resolve 'api.openweathermap.org' ([Errno 8] nodename nor servname provided, or not known)

The above exception was the direct cause of the following exception:

Traceback (most recent call last):
  File "/Library/Frameworks/Python.framework/Versions/3.10/lib/python3.10/site-packages/requests/adapters.py", line 667, in send
    resp = conn.urlopen(
  File "/Library/Frameworks/Python.framework/Versions/3.10/lib/python3.10/site-packages/urllib3/connectionpool.py", line 841, in urlopen
    retries = retries.increment(
  File "/Library/Frameworks/Python.framework/Versions/3.10/lib/python3.10/site-packages/urllib3/util/retry.py", line 519, in increment
    raise MaxRetryError(_pool, url, reason) from reason  # type: ignore[arg-type]
urllib3.exceptions.MaxRetryError: HTTPSConnectionPool(host='api.openweathermap.org', port=443): Max retries exceeded with url: /data/2.5/weather?q=Dallas&appid=e07be197f3d0a37e1661e03509a61797&units=metric (Caused by NameResolutionError("<urllib3.connection.HTTPSConnection object at 0x120fa76a0>: Failed to resolve 'api.openweathermap.org' ([Errno 8] nodename nor servname provided, or not known)"))

During handling of the above exception, another exception occurred:

Traceback (most recent call last):
  File "/Library/Frameworks/Python.framework/Versions/3.10/lib/python3.10/site-packages/airflow/task/task_runner/standard_task_runner.py", line 117, in _start_by_fork
    ret = args.func(args, dag=self.dag)
  File "/Library/Frameworks/Python.framework/Versions/3.10/lib/python3.10/site-packages/airflow/cli/cli_config.py", line 49, in command
    return func(*args, **kwargs)
  File "/Library/Frameworks/Python.framework/Versions/3.10/lib/python3.10/site-packages/airflow/utils/cli.py", line 116, in wrapper
    return f(*args, **kwargs)
  File "/Library/Frameworks/Python.framework/Versions/3.10/lib/python3.10/site-packages/airflow/cli/commands/task_command.py", line 483, in task_run
    task_return_code = _run_task_by_selected_method(args, _dag, ti)
  File "/Library/Frameworks/Python.framework/Versions/3.10/lib/python3.10/site-packages/airflow/cli/commands/task_command.py", line 256, in _run_task_by_selected_method
    return _run_raw_task(args, ti)
  File "/Library/Frameworks/Python.framework/Versions/3.10/lib/python3.10/site-packages/airflow/cli/commands/task_command.py", line 341, in _run_raw_task
    return ti._run_raw_task(
  File "/Library/Frameworks/Python.framework/Versions/3.10/lib/python3.10/site-packages/airflow/utils/session.py", line 97, in wrapper
    return func(*args, session=session, **kwargs)
  File "/Library/Frameworks/Python.framework/Versions/3.10/lib/python3.10/site-packages/airflow/models/taskinstance.py", line 3006, in _run_raw_task
    return _run_raw_task(
  File "/Library/Frameworks/Python.framework/Versions/3.10/lib/python3.10/site-packages/airflow/models/taskinstance.py", line 274, in _run_raw_task
    TaskInstance._execute_task_with_callbacks(
  File "/Library/Frameworks/Python.framework/Versions/3.10/lib/python3.10/site-packages/airflow/models/taskinstance.py", line 3161, in _execute_task_with_callbacks
    result = self._execute_task(context, task_orig)
  File "/Library/Frameworks/Python.framework/Versions/3.10/lib/python3.10/site-packages/airflow/models/taskinstance.py", line 3185, in _execute_task
    return _execute_task(self, context, task_orig)
  File "/Library/Frameworks/Python.framework/Versions/3.10/lib/python3.10/site-packages/airflow/models/taskinstance.py", line 768, in _execute_task
    result = _execute_callable(context=context, **execute_callable_kwargs)
  File "/Library/Frameworks/Python.framework/Versions/3.10/lib/python3.10/site-packages/airflow/models/taskinstance.py", line 734, in _execute_callable
    return ExecutionCallableRunner(
  File "/Library/Frameworks/Python.framework/Versions/3.10/lib/python3.10/site-packages/airflow/utils/operator_helpers.py", line 252, in run
    return self.func(*args, **kwargs)
  File "/Library/Frameworks/Python.framework/Versions/3.10/lib/python3.10/site-packages/airflow/models/baseoperator.py", line 424, in wrapper
    return func(self, *args, **kwargs)
  File "/Library/Frameworks/Python.framework/Versions/3.10/lib/python3.10/site-packages/airflow/operators/python.py", line 238, in execute
    return_value = self.execute_callable()
  File "/Library/Frameworks/Python.framework/Versions/3.10/lib/python3.10/site-packages/airflow/operators/python.py", line 256, in execute_callable
    return runner.run(*self.op_args, **self.op_kwargs)
  File "/Library/Frameworks/Python.framework/Versions/3.10/lib/python3.10/site-packages/airflow/utils/operator_helpers.py", line 252, in run
    return self.func(*args, **kwargs)
  File "/Users/Ramya_Rangaraju/Data_engineering_projects/weather_pipeline/dags/weather_pipeline_dag.py", line 35, in <lambda>
    python_callable=lambda: fetch_weather_for_cities(cities)
  File "/Users/Ramya_Rangaraju/Data_engineering_projects/weather_pipeline/scripts/fetch_weather.py", line 36, in fetch_weather_for_cities
    result = fetch_weather(city)
  File "/Users/Ramya_Rangaraju/Data_engineering_projects/weather_pipeline/scripts/fetch_weather.py", line 14, in fetch_weather
    response = requests.get(url)
  File "/Library/Frameworks/Python.framework/Versions/3.10/lib/python3.10/site-packages/requests/api.py", line 73, in get
    return request("get", url, params=params, **kwargs)
  File "/Library/Frameworks/Python.framework/Versions/3.10/lib/python3.10/site-packages/requests/api.py", line 59, in request
    return session.request(method=method, url=url, **kwargs)
  File "/Library/Frameworks/Python.framework/Versions/3.10/lib/python3.10/site-packages/requests/sessions.py", line 589, in request
    resp = self.send(prep, **send_kwargs)
  File "/Library/Frameworks/Python.framework/Versions/3.10/lib/python3.10/site-packages/requests/sessions.py", line 703, in send
    r = adapter.send(request, **kwargs)
  File "/Library/Frameworks/Python.framework/Versions/3.10/lib/python3.10/site-packages/requests/adapters.py", line 700, in send
    raise ConnectionError(e, request=request)
requests.exceptions.ConnectionError: HTTPSConnectionPool(host='api.openweathermap.org', port=443): Max retries exceeded with url: /data/2.5/weather?q=Dallas&appid=e07be197f3d0a37e1661e03509a61797&units=metric (Caused by NameResolutionError("<urllib3.connection.HTTPSConnection object at 0x120fa76a0>: Failed to resolve 'api.openweathermap.org' ([Errno 8] nodename nor servname provided, or not known)"))
[2025-04-16T17:17:51.570-0500] {local_task_job_runner.py:266} INFO - Task exited with return code 1
[2025-04-16T17:17:51.576-0500] {taskinstance.py:3901} INFO - 0 downstream tasks scheduled from follow-on schedule check
[2025-04-16T17:17:51.576-0500] {local_task_job_runner.py:245} INFO - ::endgroup::
